Workbook

Sheet WBS
A1: 프로젝트 WBS (Work Breakdown Structure)
A2: 슬기로운 실무 생활 | B2: ericshim.tistory.com | C2: | | D2: brunch.co.kr/@ericshim
A3: 프로젝트명 | E3: 기준일 | F3: 46188 | G3: ← 기준일 변경 가능 | J3: 소계 간트: | K3: 표시
A4: 클라이언트 | E4: PM
A5: 범 례 | B5: 완료 | C5: 진행중(완) | D5: 진행중(잔) | E5: 대기 | F5: 보류 | G5: 삭제 | H5: ⚠마감초과 | I5: ⚡미래완료
A6: WBS | B6: 업무명 | C6: 파트 | D6: 담당자 | E6: 등급 | F6: 시작일 | G6: 종료일 | H6: 기간 | I6: 진행률 | J6: 상태 | K6: 메세지(자동) | L6: 메모(사용자) | N6: 2026년 5월 | U6: 2026년 6월 | AY6: 2026년 7월 | CD6: 2026년 8월
N7: 46167 | O7: 46168 | P7: 46169 | Q7: 46170 | R7: 46171 | S7: 46172 | T7: 46173 | U7: 46174 | V7: 46175 | W7: 46176 | X7: 46177 | Y7: 46178 | Z7: 46179 | AA7: 46180 | AB7: 46181 | AC7: 46182 | AD7: 46183 | AE7: 46184 | AF7: 46185 | AG7: 46186 | AH7: 46187 | AI7: 46188 | AJ7: 46189 | AK7: 46190 | AL7: 46191 | AM7: 46192 | AN7: 46193 | AO7: 46194 | AP7: 46195 | AQ7: 46196 | AR7: 46197 | AS7: 46198 | AT7: 46199 | AU7: 46200 | AV7: 46201 | AW7: 46202 | AX7: 46203 | AY7: 46204 | AZ7: 46205 | BA7: 46206 | BB7: 46207 | BC7: 46208 | BD7: 46209 | BE7: 46210 | BF7: 46211 | BG7: 46212 | BH7: 46213 | BI7: 46214 | BJ7: 46215 | BK7: 46216 | BL7: 46217 | BM7: 46218 | BN7: 46219 | BO7: 46220 | BP7: 46221 | BQ7: 46222 | BR7: 46223 | BS7: 46224 | BT7: 46225 | BU7: 46226 | BV7: 46227 | BW7: 46228 | BX7: 46229 | BY7: 46230 | BZ7: 46231 | CA7: 46232 | CB7: 46233 | CC7: 46234 | CD7: 46235 | CE7: 46236 | CF7: 46237 | CG7: 46238 | CH7: 46239 | CI7: 46240 | CJ7: 46241 | CK7: 46242 | CL7: 46243 | CM7: 46244 | CN7: 46245 | CO7: 46246 | CP7: 46247 | CQ7: 46248 | CR7: 46249 | CS7: 46250 | CT7: 46251 | CU7: 46252 | CV7: 46253 | CW7: 46254 | CX7: 46255
N8: 월 | O8: 화 | P8: 수 | Q8: 목 | R8: 금 | S8: 토 | T8: 일 | U8: 월 | V8: 화 | W8: 수 | X8: 목 | Y8: 금 | Z8: 현충일 | AA8: 일 | AB8: 월 | AC8: 화 | AD8: 수 | AE8: 목 | AF8: 금 | AG8: 토 | AH8: 일 | AI8: 월 | AJ8: 화 | AK8: 수 | AL8: 목 | AM8: 금 | AN8: 토 | AO8: 일 | AP8: 월 | AQ8: 화 | AR8: 수 | AS8: 목 | AT8: 금 | AU8: 토 | AV8: 일 | AW8: 월 | AX8: 화 | AY8: 수 | AZ8: 목 | BA8: 금 | BB8: 토 | BC8: 일 | BD8: 월 | BE8: 화 | BF8: 수 | BG8: 목 | BH8: 금 | BI8: 토 | BJ8: 일 | BK8: 월 | BL8: 화 | BM8: 수 | BN8: 목 | BO8: 금 | BP8: 토 | BQ8: 일 | BR8: 월 | BS8: 화 | BT8: 수 | BU8: 목 | BV8: 금 | BW8: 토 | BX8: 일 | BY8: 월 | BZ8: 화 | CA8: 수 | CB8: 목 | CC8: 금 | CD8: 토 | CE8: 일 | CF8: 월 | CG8: 화 | CH8: 수 | CI8: 목 | CJ8: 금 | CK8: 토 | CL8: 일 | CM8: 월 | CN8: 화 | CO8: 수 | CP8: 목 | CQ8: 금 | CR8: 광복절 | CS8: 일 | CT8: 월 | CU8: 화 | CV8: 수 | CW8: 목 | CX8: 금
A9: 공휴일 표시 (Y=출근) | Z9: 휴 | CR9: 휴
A10: 기준일 → | AI10: ▼
A11: WBS | B11: 업무명 | C11: 파트 | D11: 담당자 | E11: 등급 | F11: 시작일 | G11: 종료일 | H11: 기간 | I11: 진행률 | J11: 상태 | K11: 메세지(자동) | L11: 메모(사용자)
A12: 1.0 | B12: 기획 | F12: =IFERROR(MINIFS(F13:F18,J13:J18,"<>삭제"),"") -> 46168 | G12: =IFERROR(MAXIFS(G13:G18,J13:J18,"<>삭제"),"") -> 46178 | H12: =IFERROR(G12-F12+1,"") -> 11 | I12: =IFERROR((IF(J14<>"삭제",I14,0)+IF(J15<>"삭제",I15,0)+IF(J16<>"삭제",I16,0)+IF(J17<>"삭제",I17,0)+IF(J18<>"삭제",I18,0))/(IF(J14<>"삭제",1,0)+IF(J15<>"삭제",1,0)+IF(J16<>"삭제",1,0)+IF(J17<>"삭제",1,0)+IF(J18<>"삭제",1,0)),0) -> 1
A13: 1.1 | B13: 요구사항 분석 | C13: PM | D13: 김지호 | E13: 특급 | F13: =IFERROR(MINIFS(F14:F15,J14:J15,"<>삭제"),"") -> 46168 | G13: =IFERROR(MAXIFS(G14:G15,J14:J15,"<>삭제"),"") -> 46172 | H13: =IFERROR(G13-F13+1,"") -> 5 | I13: =IFERROR((IF(J14<>"삭제",I14,0)+IF(J15<>"삭제",I15,0))/(IF(J14<>"삭제",1,0)+IF(J15<>"삭제",1,0)),0) -> 1 | J13: 완료 | K13: =IF(AND(G13<>"",G13<$F$3,J13<>"완료",J13<>"삭제",J13<>""),"⚠ 마감 초과",IF(AND(G13<>"",G13>$F$3,J13="완료"),"⚡ 미래 날짜 완료 이상",""))
A14: 1.1.1 | B14: 현황 파악 및 분석 | C14: PM | D14: 김지호 | E14: 특급 | F14: 46168 | G14: 46170 | H14: =IFERROR(G14-F14+1,"") -> 3 | I14: =IF(J14="삭제",0,IF(J14="완료",1,IFERROR(MIN(0.99,MAX(0,($F$3-F14)/(G14-F14))),0))) -> 1 | J14: 완료 | K14: =IF(AND(G14<>"",G14<$F$3,J14<>"완료",J14<>"삭제",J14<>""),"⚠ 마감 초과",IF(AND(G14<>"",G14>$F$3,J14="완료"),"⚡ 미래 날짜 완료 이상",""))
A15: 1.1.2 | B15: 요구사항 문서화 | C15: PM | D15: 김지호 | E15: 특급 | F15: 46170 | G15: 46172 | H15: =IFERROR(G15-F15+1,"") -> 3 | I15: =IF(J15="삭제",0,IF(J15="완료",1,IFERROR(MIN(0.99,MAX(0,($F$3-F15)/(G15-F15))),0))) -> 1 | J15: 완료 | K15: =IF(AND(G15<>"",G15<$F$3,J15<>"완료",J15<>"삭제",J15<>""),"⚠ 마감 초과",IF(AND(G15<>"",G15>$F$3,J15="완료"),"⚡ 미래 날짜 완료 이상",""))
A16: 1.2 | B16: 콘셉트 기획 | C16: 디자인 | D16: 이수현 | E16: 고급 | F16: 46171 | G16: 46177 | H16: =IFERROR(G16-F16+1,"") -> 7 | I16: =IF(J16="삭제",0,IF(J16="완료",1,IFERROR(MIN(0.99,MAX(0,($F$3-F16)/(G16-F16))),0))) -> 1 | J16: 완료 | K16: =IF(AND(G16<>"",G16<$F$3,J16<>"완료",J16<>"삭제",J16<>""),"⚠ 마감 초과",IF(AND(G16<>"",G16>$F$3,J16="완료"),"⚡ 미래 날짜 완료 이상",""))
A17: 1.3 | B17: 레퍼런스 조사 | C17: 디자인 | D17: 이수현 | E17: 고급 | F17: 46173 | G17: 46177 | H17: =IFERROR(G17-F17+1,"") -> 5 | I17: =IF(J17="삭제",0,IF(J17="완료",1,IFERROR(MIN(0.99,MAX(0,($F$3-F17)/(G17-F17))),0))) -> 1 | J17: 완료 | K17: =IF(AND(G17<>"",G17<$F$3,J17<>"완료",J17<>"삭제",J17<>""),"⚠ 마감 초과",IF(AND(G17<>"",G17>$F$3,J17="완료"),"⚡ 미래 날짜 완료 이상",""))
A18: 1.4 | B18: 킥오프 미팅 | C18: 전체 | D18: 김지호 | E18: 특급 | F18: 46178 | G18: 46178 | H18: =IFERROR(G18-F18+1,"") -> 1 | I18: =IF(J18="삭제",0,IF(J18="완료",1,IFERROR(MIN(0.99,MAX(0,($F$3-F18)/(G18-F18))),0))) -> 1 | J18: 완료 | K18: =IF(AND(G18<>"",G18<$F$3,J18<>"완료",J18<>"삭제",J18<>""),"⚠ 마감 초과",IF(AND(G18<>"",G18>$F$3,J18="완료"),"⚡ 미래 날짜 완료 이상",""))
A19: 2.0 | B19: 디자인 | F19: =IFERROR(MINIFS(F20:F33,J20:J33,"<>삭제"),"") -> 46179 | G19: =IFERROR(MAXIFS(G20:G33,J20:J33,"<>삭제"),"") -> 46223 | H19: =IFERROR(G19-F19+1,"") -> 45 | I19: =IFERROR((IF(J21<>"삭제",I21,0)+IF(J22<>"삭제",I22,0)+IF(J23<>"삭제",I23,0)+IF(J24<>"삭제",I24,0)+IF(J25<>"삭제",I25,0)+IF(J26<>"삭제",I26,0)+IF(J28<>"삭제",I28,0)+IF(J29<>"삭제",I29,0)+IF(J30<>"삭제",I30,0)+IF(J31<>"삭제",I31,0)+IF(J32<>"삭제",I32,0)+IF(J33<>"삭제",I33,0))/(IF(J21<>"삭제",1,0)+IF(J22<>"삭제",1,0)+IF(J23<>"삭제",1,0)+IF(J24<>"삭제",1,0)+IF(J25<>"삭제",1,0)+IF(J26<>"삭제",1,0)+IF(J28<>"삭제",1,0)+IF(J29<>"삭제",1,0)+IF(J30<>"삭제",1,0)+IF(J31<>"삭제",1,0)+IF(J32<>"삭제",1,0)+IF(J33<>"삭제",1,0)),0) -> 0.55464646
A20: 2.1 | B20: UI/UX 설계 | C20: 디자인 | D20: 이수현 | E20: 고급 | F20: =IFERROR(MINIFS(F21:F26,J21:J26,"<>삭제"),"") -> 46179 | G20: =IFERROR(MAXIFS(G21:G26,J21:J26,"<>삭제"),"") -> 46196 | H20: =IFERROR(G20-F20+1,"") -> 18 | I20: =IFERROR((IF(J21<>"삭제",I21,0)+IF(J22<>"삭제",I22,0)+IF(J23<>"삭제",I23,0)+IF(J24<>"삭제",I24,0)+IF(J25<>"삭제",I25,0)+IF(J26<>"삭제",I26,0))/(IF(J21<>"삭제",1,0)+IF(J22<>"삭제",1,0)+IF(J23<>"삭제",1,0)+IF(J24<>"삭제",1,0)+IF(J25<>"삭제",1,0)+IF(J26<>"삭제",1,0)),0) -> 0.85018519 | J20: 진행중 | K20: =IF(AND(G20<>"",G20<$F$3,J20<>"완료",J20<>"삭제",J20<>""),"⚠ 마감 초과",IF(AND(G20<>"",G20>$F$3,J20="완료"),"⚡ 미래 날짜 완료 이상",""))
A21: 2.1.1 | B21: 사용자 리서치 | C21: 디자인 | D21: 이수현 | E21: 고급 | F21: 46179 | G21: 46181 | H21: =IFERROR(G21-F21+1,"") -> 3 | I21: =IF(J21="삭제",0,IF(J21="완료",1,IFERROR(MIN(0.99,MAX(0,($F$3-F21)/(G21-F21))),0))) -> 1 | J21: 완료 | K21: =IF(AND(G21<>"",G21<$F$3,J21<>"완료",J21<>"삭제",J21<>""),"⚠ 마감 초과",IF(AND(G21<>"",G21>$F$3,J21="완료"),"⚡ 미래 날짜 완료 이상",""))
A22: 2.1.2 | B22: 정보 구조 설계 | C22: 디자인 | D22: 이수현 | E22: 고급 | F22: 46181 | G22: 46183 | H22: =IFERROR(G22-F22+1,"") -> 3 | I22: =IF(J22="삭제",0,IF(J22="완료",1,IFERROR(MIN(0.99,MAX(0,($F$3-F22)/(G22-F22))),0))) -> 1 | J22: 완료 | K22: =IF(AND(G22<>"",G22<$F$3,J22<>"완료",J22<>"삭제",J22<>""),"⚠ 마감 초과",IF(AND(G22<>"",G22>$F$3,J22="완료"),"⚡ 미래 날짜 완료 이상",""))
A23: 2.1.3 | B23: 와이어프레임 설계 | C23: 디자인 | D23: 이수현 | E23: 고급 | F23: 46183 | G23: 46186 | H23: =IFERROR(G23-F23+1,"") -> 4 | I23: =IF(J23="삭제",0,IF(J23="완료",1,IFERROR(MIN(0.99,MAX(0,($F$3-F23)/(G23-F23))),0))) -> 1 | J23: 완료 | K23: =IF(AND(G23<>"",G23<$F$3,J23<>"완료",J23<>"삭제",J23<>""),"⚠ 마감 초과",IF(AND(G23<>"",G23>$F$3,J23="완료"),"⚡ 미래 날짜 완료 이상",""))
A24: 2.1.4 | B24: UI 디자인 시스템 | C24: 디자인 | D24: 이수현 | E24: 고급 | F24: 46185 | G24: 46188 | H24: =IFERROR(G24-F24+1,"") -> 4 | I24: =IF(J24="삭제",0,IF(J24="완료",1,IFERROR(MIN(0.99,MAX(0,($F$3-F24)/(G24-F24))),0))) -> 1 | J24: 완료 | K24: =IF(AND(G24<>"",G24<$F$3,J24<>"완료",J24<>"삭제",J24<>""),"⚠ 마감 초과",IF(AND(G24<>"",G24>$F$3,J24="완료"),"⚡ 미래 날짜 완료 이상",""))
A25: 2.1.5 | B25: 프로토타입 제작 | C25: 디자인 | D25: 이수현 | E25: 고급 | F25: 46187 | G25: 46196 | H25: =IFERROR(G25-F25+1,"") -> 10 | I25: =IF(J25="삭제",0,IF(J25="완료",1,IFERROR(MIN(0.99,MAX(0,($F$3-F25)/(G25-F25))),0))) -> 0.11111111 | J25: 진행중 | K25: =IF(AND(G25<>"",G25<$F$3,J25<>"완료",J25<>"삭제",J25<>""),"⚠ 마감 초과",IF(AND(G25<>"",G25>$F$3,J25="완료"),"⚡ 미래 날짜 완료 이상",""))
A26: 2.1.6 | B26: 사용성 검토·리뷰 | C26: 디자인 | D26: 이수현 | E26: 고급 | F26: 46180 | G26: 46182 | H26: =IFERROR(G26-F26+1,"") -> 3 | I26: =IF(J26="삭제",0,IF(J26="완료",1,IFERROR(MIN(0.99,MAX(0,($F$3-F26)/(G26-F26))),0))) -> 0.99 | J26: 진행중 | K26: =IF(AND(G26<>"",G26<$F$3,J26<>"완료",J26<>"삭제",J26<>""),"⚠ 마감 초과",IF(AND(G26<>"",G26>$F$3,J26="완료"),"⚡ 미래 날짜 완료 이상","")) -> ⚠ 마감 초과
A27: 2.2 | B27: 비주얼 디자인 | C27: 디자인 | F27: =IFERROR(MINIFS(F28:F30,J28:J30,"<>삭제"),"") -> 46189 | G27: =IFERROR(MAXIFS(G28:G30,J28:J30,"<>삭제"),"") -> 46209 | H27: =IFERROR(G27-F27+1,"") -> 21 | I27: =IFERROR((IF(J28<>"삭제",I28,0)+IF(J29<>"삭제",I29,0)+IF(J30<>"삭제",I30,0))/(IF(J28<>"삭제",1,0)+IF(J29<>"삭제",1,0)+IF(J30<>"삭제",1,0)),0) -> 0 | J27: 진행중 | K27: =IF(AND(G27<>"",G27<$F$3,J27<>"완료",J27<>"삭제",J27<>""),"⚠ 마감 초과",IF(AND(G27<>"",G27>$F$3,J27="완료"),"⚡ 미래 날짜 완료 이상",""))
A28: 2.2.1 | B28: 2D 그래픽 제작 | C28: 디자인 | D28: 박민준 | E28: 중급 | F28: 46189 | G28: 46202 | H28: =IFERROR(G28-F28+1,"") -> 14 | I28: =IF(J28="삭제",0,IF(J28="완료",1,IFERROR(MIN(0.99,MAX(0,($F$3-F28)/(G28-F28))),0))) -> 0 | J28: 진행중 | K28: =IF(AND(G28<>"",G28<$F$3,J28<>"완료",J28<>"삭제",J28<>""),"⚠ 마감 초과",IF(AND(G28<>"",G28>$F$3,J28="완료"),"⚡ 미래 날짜 완료 이상",""))
A29: 2.2.2 | B29: 3D 모델링 | C29: 3D | D29: 최준혁 | E29: 고급 | F29: 46189 | G29: 46209 | H29: =IFERROR(G29-F29+1,"") -> 21 | I29: =IF(J29="삭제",0,IF(J29="완료",1,IFERROR(MIN(0.99,MAX(0,($F$3-F29)/(G29-F29))),0))) -> 0 | J29: 변경 | K29: =IF(AND(G29<>"",G29<$F$3,J29<>"완료",J29<>"삭제",J29<>""),"⚠ 마감 초과",IF(AND(G29<>"",G29>$F$3,J29="완료"),"⚡ 미래 날짜 완료 이상","")) | L29: 범위 20→35개
A30: 2.2.3 | B30: 텍스처·재질 작업 | C30: 3D | D30: 최준혁 | E30: 고급 | F30: 46203 | G30: 46209 | H30: =IFERROR(G30-F30+1,"") -> 7 | I30: =IF(J30="삭제",0,IF(J30="완료",1,IFERROR(MIN(0.99,MAX(0,($F$3-F30)/(G30-F30))),0))) -> 0 | J30: 대기 | K30: =IF(AND(G30<>"",G30<$F$3,J30<>"완료",J30<>"삭제",J30<>""),"⚠ 마감 초과",IF(AND(G30<>"",G30>$F$3,J30="완료"),"⚡ 미래 날짜 완료 이상","")) | L30: 3D 완료 후
A31: 2.3 | B31: 영상·모션 | C31: 영상 | D31: 정다은 | E31: 중급 | F31: 46203 | G31: 46223 | H31: =IFERROR(G31-F31+1,"") -> 21 | I31: =IF(J31="삭제",0,IF(J31="완료",1,IFERROR(MIN(0.99,MAX(0,($F$3-F31)/(G31-F31))),0))) -> 0 | J31: 대기 | K31: =IF(AND(G31<>"",G31<$F$3,J31<>"완료",J31<>"삭제",J31<>""),"⚠ 마감 초과",IF(AND(G31<>"",G31>$F$3,J31="완료"),"⚡ 미래 날짜 완료 이상","")) | L31: 2.2 완료 후
A32: 2.4 | B32: 인터랙티브 UI | C32: 개발 | D32: - | E32: - | F32: 46196 | G32: 46209 | H32: =IFERROR(G32-F32+1,"") -> 14 | I32: =IF(J32="삭제",0,IF(J32="완료",1,IFERROR(MIN(0.99,MAX(0,($F$3-F32)/(G32-F32))),0))) -> 0 | J32: 삭제 | K32: =IF(AND(G32<>"",G32<$F$3,J32<>"완료",J32<>"삭제",J32<>""),"⚠ 마감 초과",IF(AND(G32<>"",G32>$F$3,J32="완료"),"⚡ 미래 날짜 완료 이상",""))
A33: 2.5 | B33: 모바일 최적화 | C33: 디자인 | D33: 이수현 | E33: 고급 | F33: 46198 | G33: 46213 | H33: =IFERROR(G33-F33+1,"") -> 16 | I33: =IF(J33="삭제",0,IF(J33="완료",1,IFERROR(MIN(0.99,MAX(0,($F$3-F33)/(G33-F33))),0))) -> 1 | J33: 완료 | K33: =IF(AND(G33<>"",G33<$F$3,J33<>"완료",J33<>"삭제",J33<>""),"⚠ 마감 초과",IF(AND(G33<>"",G33>$F$3,J33="완료"),"⚡ 미래 날짜 완료 이상","")) -> ⚡ 미래 날짜 완료 이상
A34: 3.0 | B34: 개발 | F34: =IFERROR(MINIFS(F35:F44,J35:J44,"<>삭제"),"") -> 46193 | G34: =IFERROR(MAXIFS(G35:G44,J35:J44,"<>삭제"),"") -> 46230 | H34: =IFERROR(G34-F34+1,"") -> 38 | I34: =IFERROR((IF(J35<>"삭제",I35,0)+IF(J37<>"삭제",I37,0)+IF(J38<>"삭제",I38,0)+IF(J40<>"삭제",I40,0)+IF(J41<>"삭제",I41,0)+IF(J43<>"삭제",I43,0)+IF(J44<>"삭제",I44,0))/(IF(J35<>"삭제",1,0)+IF(J37<>"삭제",1,0)+IF(J38<>"삭제",1,0)+IF(J40<>"삭제",1,0)+IF(J41<>"삭제",1,0)+IF(J43<>"삭제",1,0)+IF(J44<>"삭제",1,0)),0) -> 0
A35: 3.1 | B35: 개발 환경 구축 | C35: 개발 | D35: 강태양 | E35: 고급 | F35: 46193 | G35: 46196 | H35: =IFERROR(G35-F35+1,"") -> 4 | I35: =IF(J35="삭제",0,IF(J35="완료",1,IFERROR(MIN(0.99,MAX(0,($F$3-F35)/(G35-F35))),0))) -> 0 | J35: 대기 | K35: =IF(AND(G35<>"",G35<$F$3,J35<>"완료",J35<>"삭제",J35<>""),"⚠ 마감 초과",IF(AND(G35<>"",G35>$F$3,J35="완료"),"⚡ 미래 날짜 완료 이상",""))
A36: 3.2 | B36: 프론트엔드 | C36: 개발 | D36: 강태양 | E36: 고급 | F36: =IFERROR(MINIFS(F37:F38,J37:J38,"<>삭제"),"") -> 46196 | G36: =IFERROR(MAXIFS(G37:G38,J37:J38,"<>삭제"),"") -> 46216 | H36: =IFERROR(G36-F36+1,"") -> 21 | I36: =IFERROR((IF(J37<>"삭제",I37,0)+IF(J38<>"삭제",I38,0))/(IF(J37<>"삭제",1,0)+IF(J38<>"삭제",1,0)),0) -> 0 | J36: 대기 | K36: =IF(AND(G36<>"",G36<$F$3,J36<>"완료",J36<>"삭제",J36<>""),"⚠ 마감 초과",IF(AND(G36<>"",G36>$F$3,J36="완료"),"⚡ 미래 날짜 완료 이상",""))
A37: 3.2.1 | B37: UI 컴포넌트 개발 | C37: 개발 | D37: 강태양 | E37: 고급 | F37: 46196 | G37: 46210 | H37: =IFERROR(G37-F37+1,"") -> 15 | I37: =IF(J37="삭제",0,IF(J37="완료",1,IFERROR(MIN(0.99,MAX(0,($F$3-F37)/(G37-F37))),0))) -> 0 | J37: 대기 | K37: =IF(AND(G37<>"",G37<$F$3,J37<>"완료",J37<>"삭제",J37<>""),"⚠ 마감 초과",IF(AND(G37<>"",G37>$F$3,J37="완료"),"⚡ 미래 날짜 완료 이상",""))
A38: 3.2.2 | B38: 인터랙션·애니메이션 | C38: 개발 | D38: 이개발 | E38: 중급 | F38: 46203 | G38: 46216 | H38: =IFERROR(G38-F38+1,"") -> 14 | I38: =IF(J38="삭제",0,IF(J38="완료",1,IFERROR(MIN(0.99,MAX(0,($F$3-F38)/(G38-F38))),0))) -> 0 | J38: 보류 | K38: =IF(AND(G38<>"",G38<$F$3,J38<>"완료",J38<>"삭제",J38<>""),"⚠ 마감 초과",IF(AND(G38<>"",G38>$F$3,J38="완료"),"⚡ 미래 날짜 완료 이상","")) | L38: 리소스 부족
A39: 3.3 | B39: 백엔드·서버 | C39: 개발 | D39: 홍승민 | E39: 고급 | F39: =IFERROR(MINIFS(F40:F41,J40:J41,"<>삭제"),"") -> 46203 | G39: =IFERROR(MAXIFS(G40:G41,J40:J41,"<>삭제"),"") -> 46223 | H39: =IFERROR(G39-F39+1,"") -> 21 | I39: =IFERROR((IF(J40<>"삭제",I40,0)+IF(J41<>"삭제",I41,0))/(IF(J40<>"삭제",1,0)+IF(J41<>"삭제",1,0)),0) -> 0 | J39: 대기 | K39: =IF(AND(G39<>"",G39<$F$3,J39<>"완료",J39<>"삭제",J39<>""),"⚠ 마감 초과",IF(AND(G39<>"",G39>$F$3,J39="완료"),"⚡ 미래 날짜 완료 이상",""))
A40: 3.3.1 | B40: API 설계 및 개발 | C40: 개발 | D40: 홍승민 | E40: 고급 | F40: 46203 | G40: 46216 | H40: =IFERROR(G40-F40+1,"") -> 14 | I40: =IF(J40="삭제",0,IF(J40="완료",1,IFERROR(MIN(0.99,MAX(0,($F$3-F40)/(G40-F40))),0))) -> 0 | J40: 대기 | K40: =IF(AND(G40<>"",G40<$F$3,J40<>"완료",J40<>"삭제",J40<>""),"⚠ 마감 초과",IF(AND(G40<>"",G40>$F$3,J40="완료"),"⚡ 미래 날짜 완료 이상",""))
...

Sheet 대시보드
A1: 프로젝트 진행 현황 대시보드
A2: 슬기로운 실무 생활 | B2: ericshim.tistory.com | C2: | | D2: brunch.co.kr/@ericshim
A3: 기준일 | B3: =WBS!F3 -> 46188
A4: 전체 진행률
A5: =IFERROR(AVERAGEIFS(WBS!I12:WBS!I54,WBS!J12:WBS!J54,"<>삭제",WBS!J12:WBS!J54,"<>"),0) -> 0.40029355
A7: 상태별 현황
A8: 완료 | B8: =COUNTIF(WBS!J12:WBS!J54,"완료") -> 11 | C8: =REPT("■",COUNTIF(WBS!J12:WBS!J54,"완료")) -> ■■■■■■■■■■■
A9: 진행중 | B9: =COUNTIF(WBS!J12:WBS!J54,"진행중") -> 9 | C9: =REPT("■",COUNTIF(WBS!J12:WBS!J54,"진행중")) -> ■■■■■■■■■
A10: 대기 | B10: =COUNTIF(WBS!J12:WBS!J54,"대기") -> 14 | C10: =REPT("■",COUNTIF(WBS!J12:WBS!J54,"대기")) -> ■■■■■■■■■■■■■■
A11: 보류 | B11: =COUNTIF(WBS!J12:WBS!J54,"보류") -> 2 | C11: =REPT("■",COUNTIF(WBS!J12:WBS!J54,"보류")) -> ■■
A12: 변경 | B12: =COUNTIF(WBS!J12:WBS!J54,"변경") -> 1 | C12: =REPT("■",COUNTIF(WBS!J12:WBS!J54,"변경")) -> ■
A13: 삭제 | B13: =COUNTIF(WBS!J12:WBS!J54,"삭제") -> 1 | C13: =REPT("■",COUNTIF(WBS!J12:WBS!J54,"삭제")) -> ■
